Workbook
Name a: #REF!
Name a: #REF!
Name a: #REF!
Name a: #REF!
Name a: #REF!
Name a: #REF!
Name a: #REF!
Name a: #REF!
Name a: #REF!
Name a: #REF!
Name a: #REF!
Name a: #REF!
Name a: #REF!
Name a: #REF!
Name a: #REF!
Name a: #REF!
Name a: #REF!
Name aa: #REF!
Name aa: #REF!
Name aa: #REF!
Name aa: #REF!
Name aa: #REF!
Name aa: #REF!
Name aa: #REF!
Name aa: #REF!
Name aa: #REF!
Name aa: #REF!
Name aa: #REF!
Name aa: #REF!
Name aa: #REF!
Name aa: #REF!
Name aa: #REF!
Name aa: #REF!
Name aa: #REF!
Name amr\atan33: '[1]LPT POR Schedule'!$A$4:$G$29
Name amr\celggren: '[1]LPT POR Schedule'!$A$4:$G$29
Name amr\cgoodnes: '[1]LPT POR Schedule'!$A$4:$G$29
Name amr\csharon: '[1]LPT POR Schedule'!$A$4:$G$29
Name amr\DSBRANNA: '[1]LPT POR Schedule'!$A$4:$G$29
Name amr\fsafi: '[1]LPT POR Schedule'!$A$4:$G$29
Name amr\glsylves: '[1]LPT POR Schedule'!$A$4:$G$29
Name amr\griffin: '[1]LPT POR Schedule'!$A$4:$G$29
Name amr\JASTARBU: '[1]LPT POR Schedule'!$A$4:$G$29
Name amr\jbenen: '[1]LPT POR Schedule'!$A$4:$G$29
Name amr\jpjohnso: '[1]LPT POR Schedule'!$A$4:$G$29
Name amr\jrthomp1: '[1]LPT POR Schedule'!$A$4:$G$29
Name amr\KDBRUNE: '[1]LPT POR Schedule'!$A$4:$G$29
Name amr\llbrown: '[1]LPT POR Schedule'!$A$4:$G$29
Name amr\mcamacho: '[1]LPT POR Schedule'!$A$4:$G$29
Name amr\mcho: '[1]LPT POR Schedule'!$A$4:$G$29
Name amr\menahemz: '[1]LPT POR Schedule'!$A$4:$G$29
Name amr\mfar: '[1]LPT POR Schedule'!$A$4:$G$29
Name amr\mlui: '[1]LPT POR Schedule'!$A$4:$G$29
Name amr\NGOLLAKO: '[1]LPT POR Schedule'!$A$4:$G$29
Name amr\pajolly: '[1]LPT POR Schedule'!$A$4:$G$29
Name amr\rtan2: '[1]LPT POR Schedule'!$A$4:$C$29
Name amr\ssmehta: '[1]LPT POR Schedule'!$A$4:$G$29
Name amr\wanderso: '[1]LPT POR Schedule'!$A$4:$G$29
Name amr\zlevy: '[1]LPT POR Schedule'!$A$4:$G$29
Name asas: #REF!

Sheet Legal Disclaimer
A1: Nova Lake Mobile Platform Layout Review Checklist
A2: Intel Confidential
A3: Revision: 1.0
A4: 46131
A5: Document Number: 855310
A7: You may not use or facilitate the use of this document in connection with any infringement or other legal analysis concerning Intel products described herein. You agree to grant Intel a non-exclusive, royalty-free license to any patent claim thereafter drafted which includes subject matter disclosed herein. No license (express or implied, by estoppel or otherwise) to any intellectual property rights is granted by this document. Intel technologies’ features and benefits depend on system configuration and may require enabled hardware, software or service activation. Performance varies depending on system configuration. No computer system can be absolutely secure. Check with your system manufacturer or retailer or learn more at intel.com. Intel technologies may require enabled hardware, specific software, or service activation. Check with your system manufacturer or retailer. The products described may contain design defects or errors known as errata which may cause the product to deviate from published specifications. Currently characterized errata are available on request. Intel disclaims all express and implied warranties, including without limitation, the implied warranties of merchantability, fitness for a particular purpose, and non-infringement, as well as any warranty arising from course of performance, course of dealing, or usage in trade. All information provided here is subject to change without notice. Contact your Intel representative to obtain the latest Intel product specifications and roadmaps. Copies of documents that have an order number and are referenced in this document may be obtained by calling 1-800-548-4725 or visit www.intel.com/design/literature.htm. Intel, and the Intel logo, are trademarks of Intel Corporation in the U.S. and/or other countries. *Other names and brands may be claimed as the property of others. © 2025-2026 Intel Corporation. All rights reserved.

Sheet Revision History
A1: Revision History
A2: Revision Number | B2: Description | C2: Revision Date
A3: 0.5 | B3: Initial release | C3: 45979
A4: 0.0034837963 | B4: Revision Update Only - Power Map Updated | C4: 45968
A5: 0.7 | B5: Revision Update Only | C5: 46052
A6: 0.0048726852 | B6: Revision Update Only | C6: 46108
A7: 1 | B7: Revision Update Only | C7: 46131

Sheet Instructions
A1: Steps | B1: Instructions | C1: Rows | D1: Notes
A2: 1 | B2: Define trace electrical properties (R, Resistance and C, Capacitance) | C2: 8 - 9 | D2: This is specific to the PCB stackup and trace geometry. The values in the spreadsheet are based on Intel PDG reference stackup.
A3: 2 | B3: Set up board conditions | C3: 10 - 18 | D3: Board conditions include total trace length, placement of PU, number of devices, additional components. Initial "Total MB trace length" is currently set to 25 inch or less.
A4: 3 | B4: Fine tune the board pullup (PU), Intel silicon pulldown (PD), and Intel silicon clock current assist setting | C4: 24 - 27 | D4: Based on board conditions from Step 2, the tool will provide an initial recommendation on the board PU value (rows 20 - 23). Depending on whether the recommendation is sufficient to pass, the user would have to further tune the resistors until a passing solution is found.
A5: 4 | B5: Check Pass/Fail | C5: 29, 32 - 34 | D5: If Pass, all the electrical and timing requirements of that interface are met for this set of board conditions. If Fail, refer to rows 32 - 34 for details on failure and recommendation on how to fix the failure. The recommendations typically involve going back to the previous steps.
B7: General Notes
A8: 1 | B8: Refer to the General Design Guidelines tab for additional details
A9: 2 | B9: This spreadsheet only supports 1 port/config per I2C speed mode. For multiple ports/configs, user will need to create multiple instances of this spreadsheet
A10: 3 | B10: For Intel silicon pulldown and Intel silicon clock current assist settings, refer to the "BIOS Writer Guide" for more details
A11: 4 | B11: For PU placement (rows 13 - 14), 0% represents placement closest to Intel Silicon, 100% represents placement closest to the last device

Sheet General Design Guidelines
B2: I2C/SMBus/SMLink/Display I2C/DDR5 SPD Guidelines
B3: Notes | C3: Details
B4: Stackup layer (microstrip / stripline/ dual stripline) | C4: MS/ SL/ DSL.
B5: Characteristic impedance | C5: 30 Ω to 70 Ω.
B6: Trace spacing: between SCL and other signals | C6: [1] 0.375 mm: Frequency of other signals > 1 GHz. [2] 0.250 mm: Frequency of other signals > 100 MHz. [3] 0.125 mm: Frequency of other signals ≤ 100 MHz.
B7: Trace spacing: between SDA and other signals | C7: 0.125 mm
B8: Number of vias allowed | C8: N/A
B9: Length matching between SDA and SCL signals | C9: 25.4 mm
B11: Reference
B12: Notes | C12: Details
B13: MB trace resistance per length | C13: 20 Ω/meter. Note: Board MB trace resistance number were based on PDG reference stackup.
B14: MB trace capacitance per length | C14: 208 pF/meter. Note: Board MB trace capacitance number were based on PDG reference stackup.
B16: Signal List
B17: Interface | C17: Pins/ Signals Name
B18: I2C | C18: I2C[0:5]_SDA
C19: I2C[0:5]_SCL
C20: I2C[3A:5A]_SDA
C21: I2C[3A:5A]_SCL
C22: ISH_I2C[0:2]_SDA
C23: ISH_I2C[0:2]_SCL
C24: ISH_I2C2A_SDA
C25: ISH_I2C2A_SCL
C26: THC_I2C[0:1]_SCL
C27: THC_I2C[0:1]_SDA
B28: SMLink | C28: SML[0:1]CLK
C29: SML[0:1]DATA
C30: SML[0:1]ALERT#
C31: SML0BCLK
C32: SML0BDATA
C33: SML0BALERT#
C34: PSE_SMLCLK
C35: PSE_SMLDATA
C36: PSE_SMLALERT#
C37: USB-C_SMLCLK
C38: USB-C_SMLDATA
B39: Display I2C | C39: DDPA_CTRLCLK
C40: DDPA_CTRLDATA
C41: DDP[0:2]_CTRLCLK
C42: DDP[0:2]_CTRLDATA
C43: DDP4_CTRLCLK
...

Sheet I2C Standard Mode
A1: Spec | B1: Rx strap logic | C1: strap PU | D1: strap PU (min) | E1: strap PU (max) | F1: strap PD | G1: strap PD (min) | H1: strap PD (max) | I1: Buffer Type | J1: Buffer voltage | K1: toggle PU | L1: toggle PU (min) | M1: toggle PU (max) | N1: toggle PD | O1: toggle PD (min) | P1: toggle PD (max) | Q1: current_assist_setting | R1: DC VIL | S1: DC VIH | T1: AC VIL | U1: AC VIH | V1: Rx toggle max rise time | W1: Rx toggle max fall time | X1: Strap max rise/fall time | Y1: Rx toggle min rise time | Z1: Rx toggle min fall time | AA1: min rise/fall time (EMI/RF) | AB1: silicon Cpad | AC1: base die cap | AD1: base die resistance | AE1: package cap | AF1: package resistance | AG1: Absolute/Relative | AH1: toggle PD options (Intel) | AI1: current assist options (intel) | AJ1: current_assist_min | AK1: current_assist_max
A2: Intel | B2: 1 | C2: 1000000000000 | D2: 0.1 | E2: 0.1 | F2: 1000000000000 | G2: 0.1 | H2: 0.1 | I2: OD | J2: =Summary!C16 -> 1.8 | K2: 1000000000000 | L2: 0.1 | M2: 0.1 | N2: =Summary!C26 -> 100 | O2: =Summary!C88 -> 0.25 | P2: =Summary!C89 -> 0.25 | Q2: =Summary!C27 -> N/A | R2: =Summary!C51 -> 0.3 | S2: =Summary!C52 -> 0.7 | T2: =Summary!C53 -> 0.3 | U2: =Summary!C54 -> 0.7 | V2: =Summary!C55 -> 1e-06 | W2: =Summary!C56 -> 3e-07 | X2: =V2 -> 1e-06 | Y2: =IF(Summary!C57="","",Summary!C57) | Z2: =IF(Summary!C58="","",Summary!C58) | AA2: =Summary!C59 -> 1e-10 | AB2: =Summary!C81 -> 5e-12 | AC2: =Summary!C83 -> 8.19e-12 | AD2: =Summary!C84 -> 0.69 | AE2: =Summary!C86 -> 5e-12 | AF2: =Summary!C87 -> 2.93 | AG2: =Summary!C50 -> relative | AH2: =Summary!$AF5 -> 50 | AI2: disable | AJ2: =Summary!$AF9 -> 0 | AK2: =Summary!$AF8 -> 0
A3: Device 1 | B3: 1 | C3: 1000000000000 | D3: 0.1 | E3: 0.1 | F3: 1000000000000 | G3: 0.1 | H3: 0.1 | I3: OD | J3: =Summary!C16 -> 1.8 | K3: 1000000000000 | L3: 0.1 | M3: 0.1 | N3: =Summary!C97 -> 133 | O3: =Summary!C98 -> 0.5 | P3: =Summary!C99 -> 0 | R3: =Summary!C38 -> 0.3 | S3: =Summary!C39 -> 0.7 | T3: =Summary!C42 -> 0.3 | U3: =Summary!C43 -> 0.7 | V3: =Summary!C44 -> 1e-06 | W3: =Summary!C45 -> 3e-07 | X3: =V3 -> 1e-06 | Y3: =IF(Summary!C46="","",Summary!C46) | Z3: =IF(Summary!C47="","",Summary!C47) | AA3: =Summary!C59 -> 1e-10 | AB3: =Summary!C96 -> 1e-11 | AG3: =Summary!C37 -> relative | AH3: =IF(Summary!$AG5="","",Summary!$AG5) -> 100 | AI3: =Summary!$AG7 -> 000 | AJ3: =IF(Summary!$AG9="","",IF($J$2=1.8,Summary!$AG$9,IF($J$2=3.3,Summary!$AG$11,"n/a"))) -> 2.166e-05 | AK3: =IF(Summary!$AG9="","",IF($J$2=1.8,Summary!$AG$8,IF($J$2=3.3,Summary!$AG$10,"n/a"))) -> 3.126
AH4: =IF(Summary!$AH5="","",Summary!$AH5) | AI4: =IF(Summary!$AH7="","",Summary!$AH7) -> 001 | AJ4: =IF(Summary!$AH9="","",IF($J$2=1.8,Summary!$AH$9,IF($J$2=3.3,Summary!$AH$11,"n/a"))) -> 0.6358 | AK4: =IF(Summary!$AH9="","",IF($J$2=1.8,Summary!$AH$8,IF($J$2=3.3,Summary!$AH$10,"n/a"))) -> 4.848
B5: strap voltage | F5: strap time | AH5: =IF(Summary!$AI5="","",Summary!$AI5) | AI5: =IF(Summary!$AI7="","",Summary!$AI7) -> 010 | AJ5: =IF(Summary!$AI9="","",IF($J$2=1.8,Summary!$AI$9,IF($J$2=3.3,Summary!$AI$11,"n/a"))) -> 1.256 | AK5: =IF(Summary!$AI9="","",IF($J$2=1.8,Summary!$AI$8,IF($J$2=3.3,Summary!$AI$10,"n/a"))) -> 6.53
B6: Intel Rx max | C6: Device1 Rx max | D6: Intel Rx min | E6: Device1 Rx min | F6: Intel Rx max | G6: Device1 Rx max | H6: Intel Rx min | I6: Device1 Rx min | J6: preferred max | K6: max | N6: DC Threshold Guardband | AI6: =IF(Summary!$AJ7="","",Summary!$AJ7) -> 011 | AJ6: =IF(Summary!$AJ9="","",IF($J$2=1.8,Summary!$AJ$9,IF($J$2=3.3,Summary!$AJ$11,"n/a"))) -> 1.888 | AK6: =IF(Summary!$AJ9="","",IF($J$2=1.8,Summary!$AJ$8,IF($J$2=3.3,Summary!$AJ$10,"n/a"))) -> 8.236
A7: R2 | B7: =IF(R2="N/A","", (-B25*B27*B28*B29*B31*B38-B25*B27*B28*B31*B32*B38+B25*B27*B29*B30*B31*B35-B25*B27*B29*B30*B31*B38+B25*B27*B30*B31*B32*B35-B25*B27*B30*B31*B32*B38-B25*B28*B29*B31*B32*B38+B25*B29*B30*B31*B32*B35-B25*B29*B30*B31*B32*B38+B27*B28*B29*B30*B31*B34-B27*B28*B29*B30*B31*B38+B27*B28*B30*B31*B32*B34-B27*B28*B30*B31*B32*B38+B28*B29*B30*B31*B32*B34-B28*B29*B30*B31*B32*B38) / (B25*B27*B28*B29*B38+B25*B27*B28*B31*B38+B25*B27*B28*B32*B38+B25*B27*B29*B30*B38+B25*B27*B29*B31*B38+B25*B27*B30*B31*B38+B25*B27*B30*B32*B38+B25*B27*B31*B32*B38+B25*B28*B29*B32*B38+B25*B28*B31*B32*B38+B25*B29*B30*B32*B38+B25*B29*B31*B32*B38-B25*B30*B31*B32*B36+B25*B30*B31*B32*B38-B27*B28*B29*B30*B34+B27*B28*B29*B30*B38-B27*B28*B30*B31*B34+B27*B28*B30*B31*B38-B27*B28*B30*B32*B34+B27*B28*B30*B32*B38-B27*B29*B30*B31*B34+B27*B29*B30*B31*B38-B27*B30*B31*B32*B34+B27*B30*B31*B32*B38-B28*B29*B30*B32*B34+B28*B29*B30*B32*B38-B28*B30*B31*B32*B34+B28*B30*B31*B32*B38-B29*B30*B31*B32*B34+B29*B30*B31*B32*B38)) -> 4.2732935e+08 | C7: =IF(R3="N/A","", (-C25*C27*C28*C29*C31*C40+C25*C27*C28*C31*C32*C35-C25*C27*C28*C31*C32*C40-C25*C27*C29*C30*C31*C40+C25*C27*C30*C31*C32*C35-C25*C27*C30*C31*C32*C40+C25*C28*C29*C31*C32*C36-C25*C28*C29*C31*C32*C40+C25*C29*C30*C31*C32*C36-C25*C29*C30*C31*C32*C40-C27*C28*C29*C30*C31*C40+C27*C28*C30*C31*C32*C35-C27*C28*C30*C31*C32*C40+C28*C29*C30*C31*C32*C36-C28*C29*C30*C31*C32*C40) / (C25*C27*C28*C29*C40+C25*C27*C28*C31*C40+C25*C27*C28*C32*C40+C25*C27*C29*C30*C40+C25*C27*C29*C31*C40+C25*C27*C30*C31*C40+C25*C27*C30*C32*C40+C25*C27*C31*C32*C40-C25*C28*C29*C32*C36+C25*C28*C29*C32*C40-C25*C28*C31*C32*C36+C25*C28*C31*C32*C40-C25*C29*C30*C32*C36+C25*C29*C30*C32*C40-C25*C29*C31*C32*C36+C25*C29*C31*C32*C40-C25*C30*C31*C32*C36+C25*C30*C31*C32*C40+C27*C28*C29*C30*C40+C27*C28*C30*C31*C40+C27*C28*C30*C32*C40+C27*C29*C30*C31*C40-C27*C30*C31*C32*C34+C27*C30*C31*C32*C40-C28*C29*C30*C32*C36+C28*C29*C30*C32*C40-C28*C30*C31*C32*C36+C28*C30*C31*C32*C40-C29*C30*C31*C32*C36+C29*C30*C31*C32*C40)) -> 4.2732935e+08 | D7: =IF(R2="N/A","",(-E89*E91*E92*E93*E95*E102-E89*E91*E92*E95*E96*E102+E89*E91*E93*E94*E95*E99-E89*E91*E93*E94*E95*E102+E89*E91*E94*E95*E96*E99-E89*E91*E94*E95*E96*E102-E89*E92*E93*E95*E96*E102+E89*E93*E94*E95*E96*E99-E89*E93*E94*E95*E96*E102+E91*E92*E93*E94*E95*E98-E91*E92*E93*E94*E95*E102+E91*E92*E94*E95*E96*E98-E91*E92*E94*E95*E96*E102+E92*E93*E94*E95*E96*E98-E92*E93*E94*E95*E96*E102)/( E89*E91*E92*E93*E102+E89*E91*E92*E95*E102+E89*E91*E92*E96*E102+E89*E91*E93*E94*E102+E89*E91*E93*E95*E102+E89*E91*E94*E95*E102+E89*E91*E94*E96*E102+E89*E91*E95*E96*E102+E89*E92*E93*E96*E102+E89*E92*E95*E96*E102+E89*E93*E94*E96*E102+E89*E93*E95*E96*E102-E89*E94*E95*E96*E100+E89*E94*E95*E96*E102-E91*E92*E93*E94*E98+E91*E92*E93*E94*E102-E91*E92*E94*E95*E98+E91*E92*E94*E95*E102-E91*E92*E94*E96*E98+E91*E92*E94*E96*E102-E91*E93*E94*E95*E98+E91*E93*E94*E95*E102-E91*E94*E95*E96*E98+E91*E94*E95*E96*E102-E92*E93*E94*E96*E98+E92*E93*E94*E96*E102-E92*E94*E95*E96*E98+E92*E94*E95*E96*E102-E93*E94*E95*E96*E98+E93*E94*E95*E96*E102)) -> 398.88613 | E7: =IF(R3="N/A","", (-E69*E71*E72*E73*E75*E84+E69*E71*E72*E75*E76*E79-E69*E71*E72*E75*E76*E84-E69*E71*E73*E74*E75*E84+E69*E71*E74*E75*E76*E79-E69*E71*E74*E75*E76*E84+E69*E72*E73*E75*E76*E80-E69*E72*E73*E75*E76*E84+E69*E73*E74*E75*E76*E80-E69*E73*E74*E75*E76*E84-E71*E72*E73*E74*E75*E84+E71*E72*E74*E75*E76*E79-E71*E72*E74*E75*E76*E84+E72*E73*E74*E75*E76*E80-E72*E73*E74*E75*E76*E84) / (E69*E71*E72*E73*E84+E69*E71*E72*E75*E84+E69*E71*E72*E76*E84+E69*E71*E73*E74*E84+E69*E71*E73*E75*E84+E69*E71*E74*E75*E84+E69*E71*E74*E76*E84+E69*E71*E75*E76*E84-E69*E72*E73*E76*E80+E69*E72*E73*E76*E84-E69*E72*E75*E76*E80+E69*E72*E75*E76*E84-E69*E73*E74*E76*E80+E69*E73*E74*E76*E84-E69*E73*E75*E76*E80+E69*E73*E75*E76*E84-E69*E74*E75*E76*E80+E69*E74*E75*E76*E84+E71*E72*E73*E74*E84+E71*E72*E74*E75*E84+E71*E72*E74*E76*E84+E71*E73*E74*E75*E84-E71*E74*E75*E76*E78+E71*E74*E75*E76*E84-E72*E73*E74*E76*E80+E72*E73*E74*E76*E84-E72*E74*E75*E76*E80+E72*E74*E75*E76*E84-E73*E74*E75*E76*E80+E73*E74*E75*E76*E84)) -> 378.31471 | F7: =_xlfn.IFNA(_xlfn.XLOOKUP($X$2,AB34:AB129,P34:P129,,-1), "Out of support PU range") -> 6510 | G7: =_xlfn.IFNA(_xlfn.XLOOKUP($X$3,S34:S129,P34:P129,,-1), "Out of support PU range") -> 6510 | H7: =_xlfn.IFNA(MAX(_xlfn.XLOOKUP(MAX($Y$2:$AA$2),AA34:AA129,O34:O129,,1), _xlfn.XLOOKUP($W$2,AD34:AD129,O34:O129,,-1)), "Fail AC VIL") -> 408.5 | I7: =_xlfn.IFNA(MAX(_xlfn.XLOOKUP(MAX($Y$3:$AA$3),R34:R129,O34:O129,,1), _xlfn.XLOOKUP($W$3,AC34:AC129,O34:O129,,-1)), "Fail AC VIL") -> 408.5 | J7: 20000 | K7: =MIN( MIN(FLOOR(B7,10^(LEN(ROUND(B7,0))-1))/10, FLOOR(C7,10^(LEN(ROUND(C7,0))-1))/10, IF(F7*10>=J7,FLOOR(F7,10^(LEN(ROUND(F7,0))-1))/10,FLOOR(F7,10^(LEN(ROUND(F7,0))-1))), FLOOR(G7,10^(LEN(ROUND(G7,0))-1))/10), MAX(I7,J7) ) -> 600 | N7: =Summary!C62 -> 0.02 | AI7: =IF(Summary!$AK7="","",Summary!$AK7) -> 100 | AJ7: =IF(Summary!$AK9="","",IF($J$2=1.8,Summary!$AK$9,IF($J$2=3.3,Summary!$AK$11,"n/a"))) -> 2.505 | AK7: =IF(Summary!$AK9="","",IF($J$2=1.8,Summary!$AK$8,IF($J$2=3.3,Summary!$AK$10,"n/a"))) -> 9.928
A8: R7 min | B8: =(-B25*B26*B27*B28*B29*R2-B25*B26*B27*B28*B32*R2-B25*B26*B27*B29*B30*R2-B25*B26*B27*B30*B32*R2-B25*B26*B28*B29*B32*R2-B25*B26*B29*B30*B32*R2+B26*B27*B28*B29*B30*B34-B26*B27*B28*B29*B30*R2+B26*B27*B28*B30*B32*B34-B26*B27*B28*B30*B32*R2+B26*B28*B29*B30*B32*B34-B26*B28*B29*B30*B32*R2) / (B25*B26*B27*B28*R2+B25*B26*B27*B29*R2+B25*B26*B27*B30*R2+B25*B26*B27*B32*R2+B25*B26*B28*B32*R2+B25*B26*B29*B32*R2-B25*B26*B30*B32*B36+B25*B26*B30*B32*R2+B25*B27*B28*B29*R2+B25*B27*B28*B32*R2-B25*B27*B29*B30*B35+B25*B27*B29*B30*R2-B25*B27*B30*B32*B35+B25*B27*B30*B32*R2+B25*B28*B29*B32*R2-B25*B29*B30*B32*B35+B25*B29*B30*B32*R2-B26*B27*B28*B30*B34+B26*B27*B28*B30*R2-B26*B27*B29*B30*B34+B26*B27*B29*B30*R2-B26*B27*B30*B32*B34+B26*B27*B30*B32*R2-B26*B28*B30*B32*B34+B26*B28*B30*B32*R2-B26*B29*B30*B32*B34+B26*B29*B30*B32*R2-B27*B28*B29*B30*B34+B27*B28*B29*B30*R2-B27*B28*B30*B32*B34+B27*B28*B30*B32*R2-B28*B29*B30*B32*B34+B28*B29*B30*B32*R2) -> 895.71428 | C8: =(-C25*C26*C27*C28*C29*R3-C25*C26*C27*C28*C32*R3-C25*C26*C27*C29*C30*R3-C25*C26*C27*C30*C32*R3+C25*C26*C28*C29*C32*C36-C25*C26*C28*C29*C32*R3+C25*C26*C29*C30*C32*C36-C25*C26*C29*C30*C32*R3-C26*C27*C28*C29*C30*R3-C26*C27*C28*C30*C32*R3+C26*C28*C29*C30*C32*C36-C26*C28*C29*C30*C32*R3) / (C25*C26*C27*C28*R3+C25*C26*C27*C29*R3+C25*C26*C27*C30*R3+C25*C26*C27*C32*R3-C25*C26*C28*C32*C36+C25*C26*C28*C32*R3-C25*C26*C29*C32*C36+C25*C26*C29*C32*R3-C25*C26*C30*C32*C36+C25*C26*C30*C32*R3+C25*C27*C28*C29*R3-C25*C27*C28*C32*C35+C25*C27*C28*C32*R3+C25*C27*C29*C30*R3-C25*C27*C30*C32*C35+C25*C27*C30*C32*R3-C25*C28*C29*C32*C36+C25*C28*C29*C32*R3-C25*C29*C30*C32*C36+C25*C29*C30*C32*R3+C26*C27*C28*C30*R3+C26*C27*C29*C30*R3-C26*C27*C30*C32*C34+C26*C27*C30*C32*R3-C26*C28*C30*C32*C36+C26*C28*C30*C32*R3-C26*C29*C30*C32*C36+C26*C29*C30*C32*R3+C27*C28*C29*C30*R3-C27*C28*C30*C32*C35+C27*C28*C30*C32*R3-C28*C29*C30*C32*C36+C28*C29*C30*C32*R3) -> 895.71428 | E8: =X2/(1.204*K18) -> 5182.2763 | F8: =X3/(1.204*K18) -> 5182.2763 | H8: =AA2/(1.204*K18) -> 0.51822763 | I8: =AA3/(1.204*K18) -> 0.51822763 | J8: 20000 | K8: =MIN(MIN(FLOOR(B8,10^(LEN(ROUND(B8,0))-1))/10,FLOOR(C8,10^(LEN(ROUND(C8,0))-1))/10,FLOOR(E8,10^(LEN(ROUND(E8,0))-1))/10,FLOOR(F8,10^(LEN(ROUND(F8,0))-1))/10),MAX(I8,J8)) -> 80 | AI8: =IF(Summary!$AL7="","",Summary!$AL7) -> 101 | AJ8: =IF(Summary!$AL9="","",IF($J$2=1.8,Summary!$AL$9,IF($J$2=3.3,Summary!$AL$11,"n/a"))) -> 3.134 | AK8: =IF(Summary!$AL9="","",IF($J$2=1.8,Summary!$AL$8,IF($J$2=3.3,Summary!$AL$10,"n/a"))) -> 11.7
AI9: =IF(Summary!$AM7="","",Summary!$AM7) -> 110 | AJ9: =IF(Summary!$AM9="","",IF($J$2=1.8,Summary!$AM$9,IF($J$2=3.3,Summary!$AM$11,"n/a"))) -> 3.76 | AK9: =IF(Summary!$AM9="","",IF($J$2=1.8,Summary!$AM$8,IF($J$2=3.3,Summary!$AM$10,"n/a"))) -> 13.42
D10: new strap % (with board resistor) | F10: board resistance | H10: board resistor tol % | AI10: =IF(Summary!$AN7="","",Summary!$AN7) -> 111 | AJ10: =IF(Summary!$AN9="","",IF($J$2=1.8,Summary!$AN$9,IF($J$2=3.3,Summary!$AN$11,"n/a"))) -> 4.362 | AK10: =IF(Summary!$AN9="","",IF($J$2=1.8,Summary!$AN$8,IF($J$2=3.3,Summary!$AN$10,"n/a"))) -> 15.09
A11: board PU | B11: =IF(SUM(B2:B3)=2, IF( (1/(1/F2+1/F3)) /( (1/(1/C2+1/C3)) + (1/(1/F2+1/F3)) ) <S2,"need resistor","no need"), "no need") -> need resistor | C11: =Summary!C24 -> 2200 | D11: =IF(AND(B11="no need", C11=""), "",IF(AND(B11="no need", C11>0), "please remove resistor", IF(AND(B11="need resistor", ISBLANK(C11)), "please enter resistor", (1/(1/F2+1/F3))/(1/(1/(1/(1/C2+1/C3))+1/C11)+(1/(1/F2+1/F3))) ) )) -> 1 | F11: =IF(B11="no need", 1000000000, C11) -> 2200 | G11: board PU | H11: =Summary!C25 -> 0.05 | K11: total MB trace length | N11: pkg + silicon capacitance | P11: pkg + silicon resistance | R11: Intel_VCC_max | S11: =($J$2+$J$2*Summary!$C$17) -> 1.89 | AI11: =IF(Summary!$AO7="","",Summary!$AO7) | AJ11: =IF(Summary!$AO9="","",IF($J$2=1.8,Summary!$AO$9,IF($J$2=3.3,Summary!$AO$11,"n/a"))) | AK11: =IF(Summary!$AO9="","",IF($J$2=1.8,Summary!$AO$8,IF($J$2=3.3,Summary!$AO$10,"n/a")))
A12: board PD | B12: =IF(SUM(B2:B3)=0, IF( (1/(1/F2+1/F3)) /( (1/(1/C2+1/C3)) + (1/(1/F2+1/F3)) ) >R2,"need resistor","no need"), "no need") -> no need | C12: =IF(B12="need resistor",K8,"") | D12: =IF(AND(B12="no need", C12=""), "",IF(AND(B12="no need", C12>0), "please remove resistor", IF(AND(B12="need resistor", ISBLANK(C12)), "please enter resistor", 1/(1/(1/(1/F2+1/F3))+1/C12)/((1/(1/C2+1/C3))+1/(1/(1/(1/F2+1/F3))+1/C12)) ) )) | F12: =IF(B12="no need", 1000000000, C12) -> 1000000000 | G12: board PD | H12: 0.1 | K12: =Summary!C10 -> 25 | L12: inch | N12: =SUM(AB2:AC3,AE2:AE3) -> 2.819e-11 | O12: F | P12: =Summary!C84+Summary!C87 -> 3.62 | Q12: ohm | R12: Intel_VCC_min | S12: =($J$2-$J$2*Summary!$C$17) -> 1.71 | AI12: =IF(Summary!$AP7="","",Summary!$AP7) | AJ12: =IF(Summary!$AP9="","",IF($J$2=1.8,Summary!$AP$9,IF($J$2=3.3,Summary!$AP$11,"n/a"))) | AK12: =IF(Summary!$AP9="","",IF($J$2=1.8,Summary!$AP$8,IF($J$2=3.3,Summary!$AP$10,"n/a")))
P13: estimated pkg resistance ~ 2.593ohm | R13: Dev_VCC_max | S13: =($J$3+$J$3*Summary!$C$18) -> 1.89
K14: trace resistance per length | N14: trace capacitance per length | R14: Dev_VCC_min | S14: =($J$3-$J$3*Summary!$C$18) -> 1.71
K15: =Summary!C8 -> 19.988 | L15: ohm/meter | N15: =Summary!C9 -> 2.08e-10 | O15: F/meter
A16: Measurements | F16: rise time | H16: fall time
B17: strap % (min) | C17: strap % (max) | D17: toggle high % | E17: toggle low % | F17: min | G17: max | H17: min | I17: max | K17: estimated bus capacitance (from length, stackup, etc)
A18: Intel Rx | B18: =B62 -> 0.99999743 | C18: =B42 -> 0.9999981 | D18: =B102 -> 0.99999743 | E18: =C102 -> 0.069093064 | F18: =_xlfn.LET( _xlpm.Rbus, (1/(1/((1/(1/($G$91+$G$93)+1/$G$90))+$G$92)+1/($G$89))), _xlpm.VCC, IF($AG$2="absolute",$S$13,1), _xlpm.Vspec_abs, $U$2-$N$7, (LN(1-$T$2/_xlpm.VCC)-LN(1-_xlpm.Vspec_abs/_xlpm.VCC))*$K$19*_xlpm.Rbus ) -> 2.3489258e-07 | G18: =_xlfn.LET( _xlpm.Rbus, (1/(1/((1/(1/($D$91+$D$93)+1/$D$90))+$D$92)+1/($D$89))), _xlpm.VCC, IF($AG$2="absolute",$S$14,1), _xlpm.Vspec_abs, $U$2+$N$7, (LN(1-$T$2/_xlpm.VCC)-LN(1-_xlpm.Vspec_abs/_xlpm.VCC))*$K$18*_xlpm.Rbus ) -> 3.4248187e-07 | H18: =_xlfn.LET( _xlpm.Rbus, (1/(1/((1/(1/($H$96+$H$93)+1/$H$95))+$H$92)+1/($H$94))), _xlpm.VCC, IF($AG$2="absolute",$S$14,1), _xlpm.Vspec_abs, $T$2+$N$7, _xlpm.Vspec_rel, _xlpm.Vspec_abs/_xlpm.VCC, IFERROR((LN($U$2)-LN(_xlpm.Vspec_rel))*$K$19*_xlpm.Rbus, "Vlow exceeds VIL spec") ) -> 9.3071857e-09 | I18: =_xlfn.LET( _xlpm.Rbus, (1/(1/((1/(1/($F$96+$F$93)+1/$F$95))+$F$92)+1/($F$94))), _xlpm.VCC, IF($AG$2="absolute",$S$13,1), _xlpm.Vspec_abs, $T$2-$N$7, _xlpm.Vspec_rel, _xlpm.Vspec_abs/_xlpm.VCC, IFERROR((LN($U$2)-LN(_xlpm.Vspec_rel))*$K$18*_xlpm.Rbus,"Vlow exceeds VIL spec") ) -> 2.2780367e-08 | J18: Max | K18: =Summary!C102 -> 1.6027026e-10 | L18: F | M18: =K18*1000000000000 -> 160.27026 | N18: pF | O18: =N12+K12/39.37*N15 -> 1.6027026e-10
A19: Device1 Rx | B19: =C64 -> 0.99999743 | C19: =C44 -> 0.9999981 | D19: =B84 -> 0.99999743 | E19: =C84 -> 0.065764121 | F19: =_xlfn.LET( _xlpm.Rbus,(1/(1/((1/(1/($G$77+$G$72)+1/$G$70))+$G$73)+1/($G$71))), _xlpm.VCC,IF($AG$3="absolute",$S$11,1), _xlpm.Vspec_abs,$U$3-$N$7, (LN(1-($T$3/_xlpm.VCC))-LN(1-_xlpm.Vspec_abs/_xlpm.VCC))*$K$19*_xlpm.Rbus ) -> 2.3489258e-07 | G19: =_xlfn.LET( _xlpm.Rbus, (1/(1/((1/(1/($D$77+$D$72)+1/$D$70))+$D$73)+1/($D$71))), _xlpm.VCC, IF($AG$3="absolute",$S$12,1), _xlpm.Vspec_abs, $U$3+$N$7, (LN(1-$T$3/_xlpm.VCC)-LN(1-_xlpm.Vspec_abs/_xlpm.VCC))*$K$18*_xlpm.Rbus ) -> 3.4248187e-07 | H19: =_xlfn.LET( _xlpm.Rbus, (1/(1/((1/(1/($H$74+$H$72)+1/$H$75))+$H$73)+1/($H$76))), _xlpm.VCC, IF($AG$3="absolute",$S$12,1), _xlpm.Vspec_abs, $T$3+$N$7, _xlpm.Vspec_rel, _xlpm.Vspec_abs/_xlpm.VCC, IFERROR((LN($U$3)-LN(_xlpm.Vspec_rel))*$K$19*_xlpm.Rbus, "Vlow exceeds VIL spec") ) -> 1.026249e-08 | I19: =_xlfn.LET( _xlpm.Rbus, (1/(1/((1/(1/($F$74+$F$72)+1/$F$75))+$F$73)+1/($F$76))), _xlpm.VCC, IF($AG$3="absolute",$S$11,1), _xlpm.Vspec_abs, $T$3-$N$7, _xlpm.Vspec_rel, _xlpm.Vspec_abs/_xlpm.VCC, IFERROR((LN($U$3)-LN(_xlpm.Vspec_rel))*$K$18*_xlpm.Rbus,"Vlow exceeds VIL spec") ) -> 2.1605534e-08 | J19: Min | K19: =Summary!C101 -> 1.4358026e-10 | L19: F
K20: estimated bus resistance (from length, stackup, etc)
E21: Intel Rx | F21: =IF(OR(AND(E18>(R2-N7), Summary!C50="relative"), AND(E18>(R2-N7)/(J3+J3*Summary!C18), Summary!C50="absolute")),IF(U29="no solution", "failed DC low, reduce MB trace length or increase trace width (reduce MB trace resistance per length)","failed DC low, make sure board PU is within the recommended range"),IF(OR(G18>V2,I18>W2), "failed max rise/fall time spec, recommendations:" & CHAR(10) & IF(OR(Summary!C24>Summary!C22,Summary!C24<Summary!C21), "- ensure board PU is within recommended range" & CHAR(10),) & "- reduce MB trace length","")) | J21: Max | K21: =Summary!C104 -> 22.122405 | L21: ohm
D22: recommendation #1 | E22: Device Rx | F22: {=IF(Q2="N/A","",IF(OR(G19>V3,I19>W3),IF(Q2=MAX(AJ2:AJ11),"","failed max rise/fall time spec, recommended Intel ""current_assist_setting"" strength: "&INDEX(AI2:AI11,MATCH(VLOOKUP(Q2,AI2:AI11,1,FALSE),AI2:AI11,0)+1)),IF(F19<Y3,"failed min rise time spec, recommended to use weaker board PU","")))} | J22: Min | K22: =Summary!C103 -> 16.312405 | L22: ohm
B23: max strap voltage | D23: recommendation #2 | F23: =IF(F22="",IF(OR(AND(E19<=(R3-N7), Summary!C37="relative"),AND(E19<=(R3-N7)/(J2+J2*Summary!C17), Summary!C37="absolute")),IF(OR(G19>V3,I19>W3), IF(N2=MIN(AH2:AH5), "failed max rise/fall time spec, recommendations:" & CHAR(10) & "-reduce MB trace length" & CHAR(10) & "-increase trace width (reduce MB trace resistance per length)", "failed max rise/fall time spec, recommendations:" & CHAR(10) & IF(OR(Summary!C24>Summary!C22,Summary!C24<Summary!C21), "- ensure board PU is within recommended range" & CHAR(10),) & "- recommended Intel ""toggle PD"" strength: " & VLOOKUP(MAX(N2:N3)-1,AH2:AH5,1,TRUE) & CHAR(10) & "- reduce MB trace length or increase trace width (reduce MB trace resistance per length)"),""),IF(U29="no solution", "failed DC low voltage, recommendations:" & CHAR(10) & "-reduce Intel silicon pulldown value" & CHAR(10) & "-increase trace width (reduce MB trace resistance per length)" & CHAR(10) & "-reduce MB trace length","failed DC low voltage, make sure board PU is within the recommended range")),"") | K23: PU placement location from Intel
B24: worse case for Intel Rx | C24: worse case for Device1 Rx | K24: =Summary!C13 -> 0 | L24: min
A25: R1 | B25: =C2*(1-D2) -> 900000000000 | C25: =C2*(1-D2) -> 900000000000 | K25: =Summary!C14 -> 1 | L25: max | N25: Link to summary
A26: R2 | B26: =F11*(1-H11) -> 2090 | C26: =F11*(1-H11) -> 2090 | Q26: Rpu_currentassist = VCC / (2*current_assist_value)
A27: R3 | B27: =C3*(1-D3) -> 900000000000 | C27: =C3*(1-D3) -> 900000000000 | Q27: tr(max) = constant * Rmax * C
A28: R4 | B28: =K21 -> 22.122405 | C28: 0 | Q28: Rmax = tr(max)/(constant * C) | V28: min | W28: max | X28: %
A29: R5 | B29: 0 | C29: =K21 -> 22.122405 | T29: Recommended PU | U29: =IF(IF(ISBLANK(Summary!C25),IF(U30=W82,L30,U30),IF(Summary!C25=5%,L30,U30))=N130,"no solution",IF(ISBLANK(Summary!C25),IF(U30=W82,L30,U30),IF(Summary!C25=5%,L30,U30))) -> 1600 | V29: =IFERROR(IF(X29=5%,VLOOKUP(1,M34:N129,2,FALSE),VLOOKUP(1,V34:W81,2,FALSE)),"no solution") -> 430 | W29: =IF(U29="no solution","no solution",IF(X29=5%,VLOOKUP(MAX(M34:M129)-1,M34:N129,2,FALSE),VLOOKUP(MAX(V34:V81)-1,V34:W81,2,FALSE))) -> 6200 | X29: =Summary!C25 -> 0.05
A30: R6 | B30: =F2*(1+H2) -> 1100000000000 | C30: =F2*(1+H2) -> 1100000000000 | K30: PU @ 5% | L30: =VLOOKUP(Q31,M34:Q154,2) -> 1600 | T30: PU @ 10% | U30: =VLOOKUP(Z31,V34:W82,2) -> 1800
A31: R7 | B31: =F12*(1+H12) -> 1100000000 | C31: =F12*(1+H12) -> 1100000000 | Q31: {=MAX(M34:M129+1)/2} -> 15.5 | Z31: {=MAX(V34:V81+1)/2} -> 8
A32: R8 | B32: =F3*(1+H3) -> 1100000000000 | C32: =F3*(1+H3) -> 1100000000000 | M32: 0.05 | V32: 0.1
K33: mult | N33: nom | O33: min | P33: max | Q33: if meets spec | R33: Dev_Tr_MinR | S33: Dev_Tr_MaxR | T33: mult | W33: nom | X33: min | Y33: max | Z33: if meets spec | AA33: Intel_Tr_MinR | AB33: Intel_Tr_MaxR | AC33: Dev_maxTf_minR | AD33: Intel_maxTf_minR
A34: V1 | B34: 1 | C34: 1 | K34: 1 | L34: 10 | M34: =Q34 -> 0 | N34: =L34*K34 -> 10 | O34: =N34*(1-$M$32) -> 9.5 | P34: =N34*(1+$M$32) -> 10.5 | Q34: =IF($Q$2="N/A",IF(AND((O34>=MAX($H$7:$I$7)),(P34<=MIN($F$7:$G$7)),(P34<=MIN($B$7:$C$7)),(O34>=MAX($D$7:$E$7))),1,0),IF(AND((O34>=MAX($I$7)),(P34<=MIN($G$7)),(P34<=MIN($C$7)),(O34>=MAX($E$7))),1,0)) -> 0 | R34: =_xlfn.LET( _xlpm.PU, O34, _xlpm.VCC, IF($AG$3="absolute",$S$11,1), _xlpm.Vspec_abs, $U$3-$N$7, _xlpm.Rbus, (1/(1/((1/(1/($G$69+$G$72)+1/_xlpm.PU))+$G$73)+1/($G$71))), _xlpm.Vz, ($G$69*_xlpm.PU*$G$72*$G$73*$G$76*$G$80+$G$69*_xlpm.PU*$G$72*$G$75*$G$76*$G$80+$G$69*_xlpm.PU*$G$73*$G$74*$G$76*$G$80+$G$69*_xlpm.PU*$G$73*$G$75*$G$76*$G$80+$G$69*_xlpm.PU*$G$74*$G$75*$G$76*$G$80+$G$69*$G$71*$G$72*$G$75*$G$76*$G$79+$G$69*$G$71*$G$74*$G$75*$G$76*$G$79+$G$69*$G$72*$G$73*$G$75*$G$76*$G$80+$G$69*$G$73*$G$74*$G$75*$G$76*$G$80+_xlpm.PU*$G$71*$G$74*$G$75*$G$76*$G$78+_xlpm.PU*$G$72*$G$73*$G$74*$G$76*$G$80+_xlpm.PU*$G$72*$G$74*$G$75*$G$76*$G$80+_xlpm.PU*$G$73*$G$74*$G$75*$G$76*$G$80+$G$71*$G$72*$G$74*$G$75*$G$76*$G$79+$G$72*$G$73*$G$74*$G$75*$G$76*$G$80) / ($G$69*_xlpm.PU*$G$71*$G$72*$G$73+$G$69*_xlpm.PU*$G$71*$G$72*$G$75+$G$69*_xlpm.PU*$G$71*$G$72*$G$76+$G$69*_xlpm.PU*$G$71*$G$73*$G$74+$G$69*_xlpm.PU*$G$71*$G$73*$G$75+$G$69*_xlpm.PU*$G$71*$G$74*$G$75+$G$69*_xlpm.PU*$G$71*$G$74*$G$76+$G$69*_xlpm.PU*$G$71*$G$75*$G$76+$G$69*_xlpm.PU*$G$72*$G$73*$G$76+$G$69*_xlpm.PU*$G$72*$G$75*$G$76+$G$69*_xlpm.PU*$G$73*$G$74*$G$76+$G$69*_xlpm.PU*$G$73*$G$75*$G$76+$G$69*_xlpm.PU*$G$74*$G$75*$G$76+$G$69*$G$71*$G$72*$G$73*$G$75+$G$69*$G$71*$G$72*$G$75*$G$76+$G$69*$G$71*$G$73*$G$74*$G$75+$G$69*$G$71*$G$74*$G$75*$G$76+$G$69*$G$72*$G$73*$G$75*$G$76+$G$69*$G$73*$G$74*$G$75*$G$76+_xlpm.PU*$G$71*$G$72*$G$73*$G$74+_xlpm.PU*$G$71*$G$72*$G$74*$G$75+_xlpm.PU*$G$71*$G$72*$G$74*$G$76+_xlpm.PU*$G$71*$G$73*$G$74*$G$75+_xlpm.PU*$G$71*$G$74*$G$75*$G$76+_xlpm.PU*$G$72*$G$73*$G$74*$G$76+_xlpm.PU*$G$72*$G$74*$G$75*$G$76+_xlpm.PU*$G$73*$G$74*$G$75*$G$76+$G$71*$G$72*$G$73*$G$74*$G$75+$G$71*$G$72*$G$74*$G$75*$G$76+$G$72*$G$73*$G$74*$G$75*$G$76), (LN(1-$T$3/_xlpm.VCC)-LN(1-_xlpm.Vspec_abs/_xlpm.VCC))*$K$19*_xlpm.Rbus ) -> 1.0676935e-09 | S34: =_xlfn.LET( _xlpm.PU,P34, _xlpm.VCC, IF($AG$3="absolute",$S$12,1), _xlpm.Vspec_abs, $U$3+$N$7, _xlpm.Rbus, (1/(1/((1/(1/($D$69+$D$72)+1/_xlpm.PU))+$D$73)+1/($D$71))), _xlpm.Vz, ($D$69*_xlpm.PU*$D$72*$D$73*$D$76*$D$80+$D$69*_xlpm.PU*$D$72*$D$75*$D$76*$D$80+$D$69*_xlpm.PU*$D$73*$D$74*$D$76*$D$80+$D$69*_xlpm.PU*$D$73*$D$75*$D$76*$D$80+$D$69*_xlpm.PU*$D$74*$D$75*$D$76*$D$80+$D$69*$D$71*$D$72*$D$75*$D$76*$D$79+$D$69*$D$71*$D$74*$D$75*$D$76*$D$79+$D$69*$D$72*$D$73*$D$75*$D$76*$D$80+$D$69*$D$73*$D$74*$D$75*$D$76*$D$80+_xlpm.PU*$D$71*$D$74*$D$75*$D$76*$D$78+_xlpm.PU*$D$72*$D$73*$D$74*$D$76*$D$80+_xlpm.PU*$D$72*$D$74*$D$75*$D$76*$D$80+_xlpm.PU*$D$73*$D$74*$D$75*$D$76*$D$80+$D$71*$D$72*$D$74*$D$75*$D$76*$D$79+$D$72*$D$73*$D$74*$D$75*$D$76*$D$80) / ($D$69*_xlpm.PU*$D$71*$D$72*$D$73+$D$69*_xlpm.PU*$D$71*$D$72*$D$75+$D$69*_xlpm.PU*$D$71*$D$72*$D$76+$D$69*_xlpm.PU*$D$71*$D$73*$D$74+$D$69*_xlpm.PU*$D$71*$D$73*$D$75+$D$69*_xlpm.PU*$D$71*$D$74*$D$75+$D$69*_xlpm.PU*$D$71*$D$74*$D$76+$D$69*_xlpm.PU*$D$71*$D$75*$D$76+$D$69*_xlpm.PU*$D$72*$D$73*$D$76+$D$69*_xlpm.PU*$D$72*$D$75*$D$76+$D$69*_xlpm.PU*$D$73*$D$74*$D$76+$D$69*_xlpm.PU*$D$73*$D$75*$D$76+$D$69*_xlpm.PU*$D$74*$D$75*$D$76+$D$69*$D$71*$D$72*$D$73*$D$75+$D$69*$D$71*$D$72*$D$75*$D$76+$D$69*$D$71*$D$73*$D$74*$D$75+$D$69*$D$71*$D$74*$D$75*$D$76+$D$69*$D$72*$D$73*$D$75*$D$76+$D$69*$D$73*$D$74*$D$75*$D$76+_xlpm.PU*$D$71*$D$72*$D$73*$D$74+_xlpm.PU*$D$71*$D$72*$D$74*$D$75+_xlpm.PU*$D$71*$D$72*$D$74*$D$76+_xlpm.PU*$D$71*$D$73*$D$74*$D$75+_xlpm.PU*$D$71*$D$74*$D$75*$D$76+_xlpm.PU*$D$72*$D$73*$D$74*$D$76+_xlpm.PU*$D$72*$D$74*$D$75*$D$76+_xlpm.PU*$D$73*$D$74*$D$75*$D$76+$D$71*$D$72*$D$73*$D$74*$D$75+$D$71*$D$72*$D$74*$D$75*$D$76+$D$72*$D$73*$D$74*$D$75*$D$76), (LN(1-$T$3/_xlpm.VCC)-LN(1-_xlpm.Vspec_abs/_xlpm.VCC))*$K$18*_xlpm.Rbus ) -> 4.7907359e-09 | T34: 1 | U34: 10 | V34: =Z34 -> 0 | W34: =U34*T34 -> 10 | X34: =W34*(1-$V$32) -> 9 | Y34: =W34*(1+$V$32) -> 11 | Z34: =IF($Q$2="N/A",IF(AND((X34>=MAX($H$7:$I$7)),(Y34<=MIN($F$7:$G$7)),(Y34<=MIN($B$7:$C$7)),(X34>=MAX($D$7:$E$7))),1,0),IF(AND((X34>=MAX($I$7)),(Y34<=MIN($G$7)),(Y34<=MIN($C$7)),(X34>=MAX($E$7))),1,0)) -> 0 | AA34: =_xlfn.LET( _xlpm.PU,O34, _xlpm.VCC, IF($AG$2="absolute",$S$13,1), _xlpm.Vspec_abs, $U$2-$N$7, _xlpm.Rbus, (1/(1/((1/(1/($G$91+$G$93)+1/_xlpm.PU))+$G$92)+1/($G$89))), _xlpm.Vz, ($G$89*_xlpm.PU*$G$94*$G$95*$G$96*$G$100+$G$89*$G$91*$G$93*$G$94*$G$95*$G$99+$G$89*$G$91*$G$94*$G$95*$G$96*$G$99+$G$89*$G$93*$G$94*$G$95*$G$96*$G$99+_xlpm.PU*$G$91*$G$92*$G$93*$G$94*$G$98+_xlpm.PU*$G$91*$G$92*$G$94*$G$95*$G$98+_xlpm.PU*$G$91*$G$92*$G$94*$G$96*$G$98+_xlpm.PU*$G$91*$G$93*$G$94*$G$95*$G$98+_xlpm.PU*$G$91*$G$94*$G$95*$G$96*$G$98+_xlpm.PU*$G$92*$G$93*$G$94*$G$96*$G$98+_xlpm.PU*$G$92*$G$94*$G$95*$G$96*$G$98+_xlpm.PU*$G$93*$G$94*$G$95*$G$96*$G$98+$G$91*$G$92*$G$93*$G$94*$G$95*$G$98+$G$91*$G$92*$G$94*$G$95*$G$96*$G$98+$G$92*$G$93*$G$94*$G$95*$G$96*$G$98) / ($G$89*_xlpm.PU*$G$91*$G$92*$G$93+$G$89*_xlpm.PU*$G$91*$G$92*$G$95+$G$89*_xlpm.PU*$G$91*$G$92*$G$96+$G$89*_xlpm.PU*$G$91*$G$93*$G$94+$G$89*_xlpm.PU*$G$91*$G$93*$G$95+$G$89*_xlpm.PU*$G$91*$G$94*$G$95+$G$89*_xlpm.PU*$G$91*$G$94*$G$96+$G$89*_xlpm.PU*$G$91*$G$95*$G$96+$G$89*_xlpm.PU*$G$92*$G$93*$G$96+$G$89*_xlpm.PU*$G$92*$G$95*$G$96+$G$89*_xlpm.PU*$G$93*$G$94*$G$96+$G$89*_xlpm.PU*$G$93*$G$95*$G$96+$G$89*_xlpm.PU*$G$94*$G$95*$G$96+$G$89*$G$91*$G$92*$G$93*$G$95+$G$89*$G$91*$G$92*$G$95*$G$96+$G$89*$G$91*$G$93*$G$94*$G$95+$G$89*$G$91*$G$94*$G$95*$G$96+$G$89*$G$92*$G$93*$G$95*$G$96+$G$89*$G$93*$G$94*$G$95*$G$96+_xlpm.PU*$G$91*$G$92*$G$93*$G$94+_xlpm.PU*$G$91*$G$92*$G$94*$G$95+_xlpm.PU*$G$91*$G$92*$G$94*$G$96+_xlpm.PU*$G$91*$G$93*$G$94*$G$95+_xlpm.PU*$G$91*$G$94*$G$95*$G$96+_xlpm.PU*$G$92*$G$93*$G$94*$G$96+_xlpm.PU*$G$92*$G$94*$G$95*$G$96+_xlpm.PU*$G$93*$G$94*$G$95*$G$96+$G$91*$G$92*$G$93*$G$94*$G$95+$G$91*$G$92*$G$94*$G$95*$G$96+$G$92*$G$93*$G$94*$G$95*$G$96), (LN(1-$T$2/_xlpm.VCC)-LN(1-_xlpm.Vspec_abs/_xlpm.VCC))*$K$19*_xlpm.Rbus ) -> 1.0676935e-09 | AB34: =_xlfn.LET( _xlpm.PU,P34, _xlpm.VCC, IF($AG$2="absolute",$S$14,1), _xlpm.Vspec_abs, $U$2+$N$7, _xlpm.Rbus, (1/(1/((1/(1/($D$91+$D$93)+1/_xlpm.PU))+$D$92)+1/($D$89))), _xlpm.Vz, ($D$89*_xlpm.PU*$D$94*$D$95*$D$96*$D$100+$D$89*$D$91*$D$93*$D$94*$D$95*$D$99+$D$89*$D$91*$D$94*$D$95*$D$96*$D$99+$D$89*$D$93*$D$94*$D$95*$D$96*$D$99+_xlpm.PU*$D$91*$D$92*$D$93*$D$94*$D$98+_xlpm.PU*$D$91*$D$92*$D$94*$D$95*$D$98+_xlpm.PU*$D$91*$D$92*$D$94*$D$96*$D$98+_xlpm.PU*$D$91*$D$93*$D$94*$D$95*$D$98+_xlpm.PU*$D$91*$D$94*$D$95*$D$96*$D$98+_xlpm.PU*$D$92*$D$93*$D$94*$D$96*$D$98+_xlpm.PU*$D$92*$D$94*$D$95*$D$96*$D$98+_xlpm.PU*$D$93*$D$94*$D$95*$D$96*$D$98+$D$91*$D$92*$D$93*$D$94*$D$95*$D$98+$D$91*$D$92*$D$94*$D$95*$D$96*$D$98+$D$92*$D$93*$D$94*$D$95*$D$96*$D$98) / ($D$89*_xlpm.PU*$D$91*$D$92*$D$93+$D$89*_xlpm.PU*$D$91*$D$92*$D$95+$D$89*_xlpm.PU*$D$91*$D$92*$D$96+$D$89*_xlpm.PU*$D$91*$D$93*$D$94+$D$89*_xlpm.PU*$D$91*$D$93*$D$95+$D$89*_xlpm.PU*$D$91*$D$94*$D$95+$D$89*_xlpm.PU*$D$91*$D$94*$D$96+$D$89*_xlpm.PU*$D$91*$D$95*$D$96+$D$89*_xlpm.PU*$D$92*$D$93*$D$96+$D$89*_xlpm.PU*$D$92*$D$95*$D$96+$D$89*_xlpm.PU*$D$93*$D$94*$D$96+$D$89*_xlpm.PU*$D$93*$D$95*$D$96+$D$89*_xlpm.PU*$D$94*$D$95*$D$96+$D$89*$D$91*$D$92*$D$93*$D$95+$D$89*$D$91*$D$92*$D$95*$D$96+$D$89*$D$91*$D$93*$D$94*$D$95+$D$89*$D$91*$D$94*$D$95*$D$96+$D$89*$D$92*$D$93*$D$95*$D$96+$D$89*$D$93*$D$94*$D$95*$D$96+_xlpm.PU*$D$91*$D$92*$D$93*$D$94+_xlpm.PU*$D$91*$D$92*$D$94*$D$95+_xlpm.PU*$D$91*$D$92*$D$94*$D$96+_xlpm.PU*$D$91*$D$93*$D$94*$D$95+_xlpm.PU*$D$91*$D$94*$D$95*$D$96+_xlpm.PU*$D$92*$D$93*$D$94*$D$96+_xlpm.PU*$D$92*$D$94*$D$95*$D$96+_xlpm.PU*$D$93*$D$94*$D$95*$D$96+$D$91*$D$92*$D$93*$D$94*$D$95+$D$91*$D$92*$D$94*$D$95*$D$96+$D$92*$D$93*$D$94*$D$95*$D$96), (LN(1-$T$2/_xlpm.VCC)-LN(1-_xlpm.Vspec_abs/_xlpm.VCC))*$K$18*_xlpm.Rbus ) -> 4.7907359e-09 | AC34: =_xlfn.LET( _xlpm.PU, O34, _xlpm.VCC, IF($AG$3="absolute",$S$11,1), _xlpm.Vspec_abs, $T$3-$N$7, _xlpm.Rbus, (1/(1/((1/(1/($F$74+$F$72)+1/$F$75))+$F$73)+1/($F$76))), _xlpm.VL_rel, ($F$69*_xlpm.PU*$F$72*$F$73*$F$76*$F$80+$F$69*_xlpm.PU*$F$72*$F$75*$F$76*$F$80+$F$69*_xlpm.PU*$F$73*$F$74*$F$76*$F$80+$F$69*_xlpm.PU*$F$73*$F$75*$F$76*$F$80+$F$69*_xlpm.PU*$F$74*$F$75*$F$76*$F$80+$F$69*$F$71*$F$72*$F$75*$F$76*$F$79+$F$69*$F$71*$F$74*$F$75*$F$76*$F$79+$F$69*$F$72*$F$73*$F$75*$F$76*$F$80+$F$69*$F$73*$F$74*$F$75*$F$76*$F$80+_xlpm.PU*$F$71*$F$74*$F$75*$F$76*$F$78+_xlpm.PU*$F$72*$F$73*$F$74*$F$76*$F$80+_xlpm.PU*$F$72*$F$74*$F$75*$F$76*$F$80+_xlpm.PU*$F$73*$F$74*$F$75*$F$76*$F$80+$F$71*$F$72*$F$74*$F$75*$F$76*$F$79+$F$72*$F$73*$F$74*$F$75*$F$76*$F$80) / ($F$69*_xlpm.PU*$F$71*$F$72*$F$73+$F$69*_xlpm.PU*$F$71*$F$72*$F$75+$F$69*_xlpm.PU*$F$71*$F$72*$F$76+$F$69*_xlpm.PU*$F$71*$F$73*$F$74+$F$69*_xlpm.PU*$F$71*$F$73*$F$75+$F$69*_xlpm.PU*$F$71*$F$74*$F$75+$F$69*_xlpm.PU*$F$71*$F$74*$F$76+$F$69*_xlpm.PU*$F$71*$F$75*$F$76+$F$69*_xlpm.PU*$F$72*$F$73*$F$76+$F$69*_xlpm.PU*$F$72*$F$75*$F$76+$F$69*_xlpm.PU*$F$73*$F$74*$F$76+$F$69*_xlpm.PU*$F$73*$F$75*$F$76+$F$69*_xlpm.PU*$F$74*$F$75*$F$76+$F$69*$F$71*$F$72*$F$73*$F$75+$F$69*$F$71*$F$72*$F$75*$F$76+$F$69*$F$71*$F$73*$F$74*$F$75+$F$69*$F$71*$F$74*$F$75*$F$76+$F$69*$F$72*$F$73*$F$75*$F$76+$F$69*$F$73*$F$74*$F$75*$F$76+_xlpm.PU*$F$71*$F$72*$F$73*$F$74+_xlpm.PU*$F$71*$F$72*$F$74*$F$75+_xlpm.PU*$F$71*$F$72*$F$74*$F$76+_xlpm.PU*$F$71*$F$73*$F$74*$F$75+_xlpm.PU*$F$71*$F$74*$F$75*$F$76+_xlpm.PU*$F$72*$F$73*$F$74*$F$76+_xlpm.PU*$F$72*$F$74*$F$75*$F$76+_xlpm.PU*$F$73*$F$74*$F$75*$F$76+$F$71*$F$72*$F$73*$F$74*$F$75+$F$71*$F$72*$F$74*$F$75*$F$76+$F$72*$F$73*$F$74*$F$75*$F$76), _xlpm.Vspec_rel, (_xlpm.Vspec_abs/_xlpm.VCC-_xlpm.VL_rel)/(1-_xlpm.VL_rel), _xlpm.Tf_max, (LN($D$19-_xlpm.VL_rel)-LN(_xlpm.Vspec_rel))*$K$18*_xlpm.Rbus, IF(_xlpm.Vspec_rel<=0,"Vlow exceeds VIL spec",_xlpm.Tf_max) ) -> Vlow exceeds VIL spec | AD34: =_xlfn.LET( _xlpm.PU, O34, _xlpm.VCC, IF($AG$2="absolute",$S$13,1), _xlpm.Vspec_abs, $T$2-$N$7, _xlpm.Rbus, (1/(1/((1/(1/($F$96+$F$93)+1/$F$95))+$F$92)+1/($F$94))), _xlpm.VL_rel, ($F$89*_xlpm.PU*$F$94*$F$95*$F$96*$F$100+$F$89*$F$91*$F$93*$F$94*$F$95*$F$99+$F$89*$F$91*$F$94*$F$95*$F$96*$F$99+$F$89*$F$93*$F$94*$F$95*$F$96*$F$99+_xlpm.PU*$F$91*$F$92*$F$93*$F$94*$F$98+_xlpm.PU*$F$91*$F$92*$F$94*$F$95*$F$98+_xlpm.PU*$F$91*$F$92*$F$94*$F$96*$F$98+_xlpm.PU*$F$91*$F$93*$F$94*$F$95*$F$98+_xlpm.PU*$F$91*$F$94*$F$95*$F$96*$F$98+_xlpm.PU*$F$92*$F$93*$F$94*$F$96*$F$98+_xlpm.PU*$F$92*$F$94*$F$95*$F$96*$F$98+_xlpm.PU*$F$93*$F$94*$F$95*$F$96*$F$98+$F$91*$F$92*$F$93*$F$94*$F$95*$F$98+$F$91*$F$92*$F$94*$F$95*$F$96*$F$98+$F$92*$F$93*$F$94*$F$95*$F$96*$F$98) / ($F$89*_xlpm.PU*$F$91*$F$92*$F$93+$F$89*_xlpm.PU*$F$91*$F$92*$F$95+$F$89*_xlpm.PU*$F$91*$F$92*$F$96+$F$89*_xlpm.PU*$F$91*$F$93*$F$94+$F$89*_xlpm.PU*$F$91*$F$93*$F$95+$F$89*_xlpm.PU*$F$91*$F$94*$F$95+$F$89*_xlpm.PU*$F$91*$F$94*$F$96+$F$89*_xlpm.PU*$F$91*$F$95*$F$96+$F$89*_xlpm.PU*$F$92*$F$93*$F$96+$F$89*_xlpm.PU*$F$92*$F$95*$F$96+$F$89*_xlpm.PU*$F$93*$F$94*$F$96+$F$89*_xlpm.PU*$F$93*$F$95*$F$96+$F$89*_xlpm.PU*$F$94*$F$95*$F$96+$F$89*$F$91*$F$92*$F$93*$F$95+$F$89*$F$91*$F$92*$F$95*$F$96+$F$89*$F$91*$F$93*$F$94*$F$95+$F$89*$F$91*$F$94*$F$95*$F$96+$F$89*$F$92*$F$93*$F$95*$F$96+$F$89*$F$93*$F$94*$F$95*$F$96+_xlpm.PU*$F$91*$F$92*$F$93*$F$94+_xlpm.PU*$F$91*$F$92*$F$94*$F$95+_xlpm.PU*$F$91*$F$92*$F$94*$F$96+_xlpm.PU*$F$91*$F$93*$F$94*$F$95+_xlpm.PU*$F$91*$F$94*$F$95*$F$96+_xlpm.PU*$F$92*$F$93*$F$94*$F$96+_xlpm.PU*$F$92*$F$94*$F$95*$F$96+_xlpm.PU*$F$93*$F$94*$F$95*$F$96+$F$91*$F$92*$F$93*$F$94*$F$95+$F$91*$F$92*$F$94*$F$95*$F$96+$F$92*$F$93*$F$94*$F$95*$F$96), _xlpm.Vspec_rel, (_xlpm.Vspec_abs/_xlpm.VCC-_xlpm.VL_rel)/(1-_xlpm.VL_rel), _xlpm.Tf_max, (LN($D$18-_xlpm.VL_rel)-LN(_xlpm.Vspec_rel))*$K$18*_xlpm.Rbus, IF(_xlpm.Vspec_rel<=0,"Vlow exceeds VIL spec",_xlpm.Tf_max) ) -> Vlow exceeds VIL spec
A35: V2 | B35: 1 | C35: 1 | K35: 1 | L35: 11 | M35: =IF(AND(Q34=1,Q35=0),Q35+M34+1, Q35+M34) -> 0 | N35: =L35*K35 -> 11 | O35: =N35*(1-$M$32) -> 10.45 | P35: =N35*(1+$M$32) -> 11.55 | Q35: =IF($Q$2="N/A",IF(AND((O35>=MAX($H$7:$I$7)),(P35<=MIN($F$7:$G$7)),(P35<=MIN($B$7:$C$7)),(O35>=MAX($D$7:$E$7))),1,0),IF(AND((O35>=MAX($I$7)),(P35<=MIN($G$7)),(P35<=MIN($C$7)),(O35>=MAX($E$7))),1,0)) -> 0 | R35: =_xlfn.LET( _xlpm.PU, O35, _xlpm.VCC, IF($AG$3="absolute",$S$11,1), _xlpm.Vspec_abs, $U$3-$N$7, _xlpm.Rbus, (1/(1/((1/(1/($G$69+$G$72)+1/_xlpm.PU))+$G$73)+1/($G$71))), _xlpm.Vz, ($G$69*_xlpm.PU*$G$72*$G$73*$G$76*$G$80+$G$69*_xlpm.PU*$G$72*$G$75*$G$76*$G$80+$G$69*_xlpm.PU*$G$73*$G$74*$G$76*$G$80+$G$69*_xlpm.PU*$G$73*$G$75*$G$76*$G$80+$G$69*_xlpm.PU*$G$74*$G$75*$G$76*$G$80+$G$69*$G$71*$G$72*$G$75*$G$76*$G$79+$G$69*$G$71*$G$74*$G$75*$G$76*$G$79+$G$69*$G$72*$G$73*$G$75*$G$76*$G$80+$G$69*$G$73*$G$74*$G$75*$G$76*$G$80+_xlpm.PU*$G$71*$G$74*$G$75*$G$76*$G$78+_xlpm.PU*$G$72*$G$73*$G$74*$G$76*$G$80+_xlpm.PU*$G$72*$G$74*$G$75*$G$76*$G$80+_xlpm.PU*$G$73*$G$74*$G$75*$G$76*$G$80+$G$71*$G$72*$G$74*$G$75*$G$76*$G$79+$G$72*$G$73*$G$74*$G$75*$G$76*$G$80) / ($G$69*_xlpm.PU*$G$71*$G$72*$G$73+$G$69*_xlpm.PU*$G$71*$G$72*$G$75+$G$69*_xlpm.PU*$G$71*$G$72*$G$76+$G$69*_xlpm.PU*$G$71*$G$73*$G$74+$G$69*_xlpm.PU*$G$71*$G$73*$G$75+$G$69*_xlpm.PU*$G$71*$G$74*$G$75+$G$69*_xlpm.PU*$G$71*$G$74*$G$76+$G$69*_xlpm.PU*$G$71*$G$75*$G$76+$G$69*_xlpm.PU*$G$72*$G$73*$G$76+$G$69*_xlpm.PU*$G$72*$G$75*$G$76+$G$69*_xlpm.PU*$G$73*$G$74*$G$76+$G$69*_xlpm.PU*$G$73*$G$75*$G$76+$G$69*_xlpm.PU*$G$74*$G$75*$G$76+$G$69*$G$71*$G$72*$G$73*$G$75+$G$69*$G$71*$G$72*$G$75*$G$76+$G$69*$G$71*$G$73*$G$74*$G$75+$G$69*$G$71*$G$74*$G$75*$G$76+$G$69*$G$72*$G$73*$G$75*$G$76+$G$69*$G$73*$G$74*$G$75*$G$76+_xlpm.PU*$G$71*$G$72*$G$73*$G$74+_xlpm.PU*$G$71*$G$72*$G$74*$G$75+_xlpm.PU*$G$71*$G$72*$G$74*$G$76+_xlpm.PU*$G$71*$G$73*$G$74*$G$75+_xlpm.PU*$G$71*$G$74*$G$75*$G$76+_xlpm.PU*$G$72*$G$73*$G$74*$G$76+_xlpm.PU*$G$72*$G$74*$G$75*$G$76+_xlpm.PU*$G$73*$G$74*$G$75*$G$76+$G$71*$G$72*$G$73*$G$74*$G$75+$G$71*$G$72*$G$74*$G$75*$G$76+$G$72*$G$73*$G$74*$G$75*$G$76), (LN(1-$T$3/_xlpm.VCC)-LN(1-_xlpm.Vspec_abs/_xlpm.VCC))*$K$19*_xlpm.Rbus ) -> 1.1744629e-09 | S35: =_xlfn.LET( _xlpm.PU,P35, _xlpm.VCC, IF($AG$3="absolute",$S$12,1), _xlpm.Vspec_abs, $U$3+$N$7, _xlpm.Rbus, (1/(1/((1/(1/($D$69+$D$72)+1/_xlpm.PU))+$D$73)+1/($D$71))), _xlpm.Vz, ($D$69*_xlpm.PU*$D$72*$D$73*$D$76*$D$80+$D$69*_xlpm.PU*$D$72*$D$75*$D$76*$D$80+$D$69*_xlpm.PU*$D$73*$D$74*$D$76*$D$80+$D$69*_xlpm.PU*$D$73*$D$75*$D$76*$D$80+$D$69*_xlpm.PU*$D$74*$D$75*$D$76*$D$80+$D$69*$D$71*$D$72*$D$75*$D$76*$D$79+$D$69*$D$71*$D$74*$D$75*$D$76*$D$79+$D$69*$D$72*$D$73*$D$75*$D$76*$D$80+$D$69*$D$73*$D$74*$D$75*$D$76*$D$80+_xlpm.PU*$D$71*$D$74*$D$75*$D$76*$D$78+_xlpm.PU*$D$72*$D$73*$D$74*$D$76*$D$80+_xlpm.PU*$D$72*$D$74*$D$75*$D$76*$D$80+_xlpm.PU*$D$73*$D$74*$D$75*$D$76*$D$80+$D$71*$D$72*$D$74*$D$75*$D$76*$D$79+$D$72*$D$73*$D$74*$D$75*$D$76*$D$80) / ($D$69*_xlpm.PU*$D$71*$D$72*$D$73+$D$69*_xlpm.PU*$D$71*$D$72*$D$75+$D$69*_xlpm.PU*$D$71*$D$72*$D$76+$D$69*_xlpm.PU*$D$71*$D$73*$D$74+$D$69*_xlpm.PU*$D$71*$D$73*$D$75+$D$69*_xlpm.PU*$D$71*$D$74*$D$75+$D$69*_xlpm.PU*$D$71*$D$74*$D$76+$D$69*_xlpm.PU*$D$71*$D$75*$D$76+$D$69*_xlpm.PU*$D$72*$D$73*$D$76+$D$69*_xlpm.PU*$D$72*$D$75*$D$76+$D$69*_xlpm.PU*$D$73*$D$74*$D$76+$D$69*_xlpm.PU*$D$73*$D$75*$D$76+$D$69*_xlpm.PU*$D$74*$D$75*$D$76+$D$69*$D$71*$D$72*$D$73*$D$75+$D$69*$D$71*$D$72*$D$75*$D$76+$D$69*$D$71*$D$73*$D$74*$D$75+$D$69*$D$71*$D$74*$D$75*$D$76+$D$69*$D$72*$D$73*$D$75*$D$76+$D$69*$D$73*$D$74*$D$75*$D$76+_xlpm.PU*$D$71*$D$72*$D$73*$D$74+_xlpm.PU*$D$71*$D$72*$D$74*$D$75+_xlpm.PU*$D$71*$D$72*$D$74*$D$76+_xlpm.PU*$D$71*$D$73*$D$74*$D$75+_xlpm.PU*$D$71*$D$74*$D$75*$D$76+_xlpm.PU*$D$72*$D$73*$D$74*$D$76+_xlpm.PU*$D$72*$D$74*$D$75*$D$76+_xlpm.PU*$D$73*$D$74*$D$75*$D$76+$D$71*$D$72*$D$73*$D$74*$D$75+$D$71*$D$72*$D$74*$D$75*$D$76+$D$72*$D$73*$D$74*$D$75*$D$76), (LN(1-$T$3/_xlpm.VCC)-LN(1-_xlpm.Vspec_abs/_xlpm.VCC))*$K$18*_xlpm.Rbus ) -> 4.9449327e-09 | T35: 1 | U35: 12 | V35: =IF(AND(Z34=1,Z35=0),Z35+V34+1, Z35+V34) -> 0 | W35: =U35*T35 -> 12 | X35: =W35*(1-$V$32) -> 10.8 | Y35: =W35*(1+$V$32) -> 13.2 | Z35: =IF($Q$2="N/A",IF(AND((X35>=MAX($H$7:$I$7)),(Y35<=MIN($F$7:$G$7)),(Y35<=MIN($B$7:$C$7)),(X35>=MAX($D$7:$E$7))),1,0),IF(AND((X35>=MAX($I$7)),(Y35<=MIN($G$7)),(Y35<=MIN($C$7)),(X35>=MAX($E$7))),1,0)) -> 0 | AA35: =_xlfn.LET( _xlpm.PU,O35, _xlpm.VCC, IF($AG$2="absolute",$S$13,1), _xlpm.Vspec_abs, $U$2-$N$7, _xlpm.Rbus, (1/(1/((1/(1/($G$91+$G$93)+1/_xlpm.PU))+$G$92)+1/($G$89))), _xlpm.Vz, ($G$89*_xlpm.PU*$G$94*$G$95*$G$96*$G$100+$G$89*$G$91*$G$93*$G$94*$G$95*$G$99+$G$89*$G$91*$G$94*$G$95*$G$96*$G$99+$G$89*$G$93*$G$94*$G$95*$G$96*$G$99+_xlpm.PU*$G$91*$G$92*$G$93*$G$94*$G$98+_xlpm.PU*$G$91*$G$92*$G$94*$G$95*$G$98+_xlpm.PU*$G$91*$G$92*$G$94*$G$96*$G$98+_xlpm.PU*$G$91*$G$93*$G$94*$G$95*$G$98+_xlpm.PU*$G$91*$G$94*$G$95*$G$96*$G$98+_xlpm.PU*$G$92*$G$93*$G$94*$G$96*$G$98+_xlpm.PU*$G$92*$G$94*$G$95*$G$96*$G$98+_xlpm.PU*$G$93*$G$94*$G$95*$G$96*$G$98+$G$91*$G$92*$G$93*$G$94*$G$95*$G$98+$G$91*$G$92*$G$94*$G$95*$G$96*$G$98+$G$92*$G$93*$G$94*$G$95*$G$96*$G$98) / ($G$89*_xlpm.PU*$G$91*$G$92*$G$93+$G$89*_xlpm.PU*$G$91*$G$92*$G$95+$G$89*_xlpm.PU*$G$91*$G$92*$G$96+$G$89*_xlpm.PU*$G$91*$G$93*$G$94+$G$89*_xlpm.PU*$G$91*$G$93*$G$95+$G$89*_xlpm.PU*$G$91*$G$94*$G$95+$G$89*_xlpm.PU*$G$91*$G$94*$G$96+$G$89*_xlpm.PU*$G$91*$G$95*$G$96+$G$89*_xlpm.PU*$G$92*$G$93*$G$96+$G$89*_xlpm.PU*$G$92*$G$95*$G$96+$G$89*_xlpm.PU*$G$93*$G$94*$G$96+$G$89*_xlpm.PU*$G$93*$G$95*$G$96+$G$89*_xlpm.PU*$G$94*$G$95*$G$96+$G$89*$G$91*$G$92*$G$93*$G$95+$G$89*$G$91*$G$92*$G$95*$G$96+$G$89*$G$91*$G$93*$G$94*$G$95+$G$89*$G$91*$G$94*$G$95*$G$96+$G$89*$G$92*$G$93*$G$95*$G$96+$G$89*$G$93*$G$94*$G$95*$G$96+_xlpm.PU*$G$91*$G$92*$G$93*$G$94+_xlpm.PU*$G$91*$G$92*$G$94*$G$95+_xlpm.PU*$G$91*$G$92*$G$94*$G$96+_xlpm.PU*$G$91*$G$93*$G$94*$G$95+_xlpm.PU*$G$91*$G$94*$G$95*$G$96+_xlpm.PU*$G$92*$G$93*$G$94*$G$96+_xlpm.PU*$G$92*$G$94*$G$95*$G$96+_xlpm.PU*$G$93*$G$94*$G$95*$G$96+$G$91*$G$92*$G$93*$G$94*$G$95+$G$91*$G$92*$G$94*$G$95*$G$96+$G$92*$G$93*$G$94*$G$95*$G$96), (LN(1-$T$2/_xlpm.VCC)-LN(1-_xlpm.Vspec_abs/_xlpm.VCC))*$K$19*_xlpm.Rbus ) -> 1.1744629e-09 | AB35: =_xlfn.LET( _xlpm.PU,P35, _xlpm.VCC, IF($AG$2="absolute",$S$14,1), _xlpm.Vspec_abs, $U$2+$N$7, _xlpm.Rbus, (1/(1/((1/(1/($D$91+$D$93)+1/_xlpm.PU))+$D$92)+1/($D$89))), _xlpm.Vz, ($D$89*_xlpm.PU*$D$94*$D$95*$D$96*$D$100+$D$89*$D$91*$D$93*$D$94*$D$95*$D$99+$D$89*$D$91*$D$94*$D$95*$D$96*$D$99+$D$89*$D$93*$D$94*$D$95*$D$96*$D$99+_xlpm.PU*$D$91*$D$92*$D$93*$D$94*$D$98+_xlpm.PU*$D$91*$D$92*$D$94*$D$95*$D$98+_xlpm.PU*$D$91*$D$92*$D$94*$D$96*$D$98+_xlpm.PU*$D$91*$D$93*$D$94*$D$95*$D$98+_xlpm.PU*$D$91*$D$94*$D$95*$D$96*$D$98+_xlpm.PU*$D$92*$D$93*$D$94*$D$96*$D$98+_xlpm.PU*$D$92*$D$94*$D$95*$D$96*$D$98+_xlpm.PU*$D$93*$D$94*$D$95*$D$96*$D$98+$D$91*$D$92*$D$93*$D$94*$D$95*$D$98+$D$91*$D$92*$D$94*$D$95*$D$96*$D$98+$D$92*$D$93*$D$94*$D$95*$D$96*$D$98) / ($D$89*_xlpm.PU*$D$91*$D$92*$D$93+$D$89*_xlpm.PU*$D$91*$D$92*$D$95+$D$89*_xlpm.PU*$D$91*$D$92*$D$96+$D$89*_xlpm.PU*$D$91*$D$93*$D$94+$D$89*_xlpm.PU*$D$91*$D$93*$D$95+$D$89*_xlpm.PU*$D$91*$D$94*$D$95+$D$89*_xlpm.PU*$D$91*$D$94*$D$96+$D$89*_xlpm.PU*$D$91*$D$95*$D$96+$D$89*_xlpm.PU*$D$92*$D$93*$D$96+$D$89*_xlpm.PU*$D$92*$D$95*$D$96+$D$89*_xlpm.PU*$D$93*$D$94*$D$96+$D$89*_xlpm.PU*$D$93*$D$95*$D$96+$D$89*_xlpm.PU*$D$94*$D$95*$D$96+$D$89*$D$91*$D$92*$D$93*$D$95+$D$89*$D$91*$D$92*$D$95*$D$96+$D$89*$D$91*$D$93*$D$94*$D$95+$D$89*$D$91*$D$94*$D$95*$D$96+$D$89*$D$92*$D$93*$D$95*$D$96+$D$89*$D$93*$D$94*$D$95*$D$96+_xlpm.PU*$D$91*$D$92*$D$93*$D$94+_xlpm.PU*$D$91*$D$92*$D$94*$D$95+_xlpm.PU*$D$91*$D$92*$D$94*$D$96+_xlpm.PU*$D$91*$D$93*$D$94*$D$95+_xlpm.PU*$D$91*$D$94*$D$95*$D$96+_xlpm.PU*$D$92*$D$93*$D$94*$D$96+_xlpm.PU*$D$92*$D$94*$D$95*$D$96+_xlpm.PU*$D$93*$D$94*$D$95*$D$96+$D$91*$D$92*$D$93*$D$94*$D$95+$D$91*$D$92*$D$94*$D$95*$D$96+$D$92*$D$93*$D$94*$D$95*$D$96), (LN(1-$T$2/_xlpm.VCC)-LN(1-_xlpm.Vspec_abs/_xlpm.VCC))*$K$18*_xlpm.Rbus ) -> 4.9449327e-09 | AC35: =_xlfn.LET( _xlpm.PU, O35, _xlpm.VCC, IF($AG$3="absolute",$S$11,1), _xlpm.Vspec_abs, $T$3-$N$7, _xlpm.Rbus, (1/(1/((1/(1/($F$74+$F$72)+1/$F$75))+$F$73)+1/($F$76))), _xlpm.VL_rel, ($F$69*_xlpm.PU*$F$72*$F$73*$F$76*$F$80+$F$69*_xlpm.PU*$F$72*$F$75*$F$76*$F$80+$F$69*_xlpm.PU*$F$73*$F$74*$F$76*$F$80+$F$69*_xlpm.PU*$F$73*$F$75*$F$76*$F$80+$F$69*_xlpm.PU*$F$74*$F$75*$F$76*$F$80+$F$69*$F$71*$F$72*$F$75*$F$76*$F$79+$F$69*$F$71*$F$74*$F$75*$F$76*$F$79+$F$69*$F$72*$F$73*$F$75*$F$76*$F$80+$F$69*$F$73*$F$74*$F$75*$F$76*$F$80+_xlpm.PU*$F$71*$F$74*$F$75*$F$76*$F$78+_xlpm.PU*$F$72*$F$73*$F$74*$F$76*$F$80+_xlpm.PU*$F$72*$F$74*$F$75*$F$76*$F$80+_xlpm.PU*$F$73*$F$74*$F$75*$F$76*$F$80+$F$71*$F$72*$F$74*$F$75*$F$76*$F$79+$F$72*$F$73*$F$74*$F$75*$F$76*$F$80) / ($F$69*_xlpm.PU*$F$71*$F$72*$F$73+$F$69*_xlpm.PU*$F$71*$F$72*$F$75+$F$69*_xlpm.PU*$F$71*$F$72*$F$76+$F$69*_xlpm.PU*$F$71*$F$73*$F$74+$F$69*_xlpm.PU*$F$71*$F$73*$F$75+$F$69*_xlpm.PU*$F$71*$F$74*$F$75+$F$69*_xlpm.PU*$F$71*$F$74*$F$76+$F$69*_xlpm.PU*$F$71*$F$75*$F$76+$F$69*_xlpm.PU*$F$72*$F$73*$F$76+$F$69*_xlpm.PU*$F$72*$F$75*$F$76+$F$69*_xlpm.PU*$F$73*$F$74*$F$76+$F$69*_xlpm.PU*$F$73*$F$75*$F$76+$F$69*_xlpm.PU*$F$74*$F$75*$F$76+$F$69*$F$71*$F$72*$F$73*$F$75+$F$69*$F$71*$F$72*$F$75*$F$76+$F$69*$F$71*$F$73*$F$74*$F$75+$F$69*$F$71*$F$74*$F$75*$F$76+$F$69*$F$72*$F$73*$F$75*$F$76+$F$69*$F$73*$F$74*$F$75*$F$76+_xlpm.PU*$F$71*$F$72*$F$73*$F$74+_xlpm.PU*$F$71*$F$72*$F$74*$F$75+_xlpm.PU*$F$71*$F$72*$F$74*$F$76+_xlpm.PU*$F$71*$F$73*$F$74*$F$75+_xlpm.PU*$F$71*$F$74*$F$75*$F$76+_xlpm.PU*$F$72*$F$73*$F$74*$F$76+_xlpm.PU*$F$72*$F$74*$F$75*$F$76+_xlpm.PU*$F$73*$F$74*$F$75*$F$76+$F$71*$F$72*$F$73*$F$74*$F$75+$F$71*$F$72*$F$74*$F$75*$F$76+$F$72*$F$73*$F$74*$F$75*$F$76), _xlpm.Vspec_rel, (_xlpm.Vspec_abs/_xlpm.VCC-_xlpm.VL_rel)/(1-_xlpm.VL_rel), _xlpm.Tf_max, (LN($D$19-_xlpm.VL_rel)-LN(_xlpm.Vspec_rel))*$K$18*_xlpm.Rbus, IF(_xlpm.Vspec_rel<=0,"Vlow exceeds VIL spec",_xlpm.Tf_max) ) -> Vlow exceeds VIL spec | AD35: =_xlfn.LET( _xlpm.PU, O35, _xlpm.VCC, IF($AG$2="absolute",$S$13,1), _xlpm.Vspec_abs, $T$2-$N$7, _xlpm.Rbus, (1/(1/((1/(1/($F$96+$F$93)+1/$F$95))+$F$92)+1/($F$94))), _xlpm.VL_rel, ($F$89*_xlpm.PU*$F$94*$F$95*$F$96*$F$100+$F$89*$F$91*$F$93*$F$94*$F$95*$F$99+$F$89*$F$91*$F$94*$F$95*$F$96*$F$99+$F$89*$F$93*$F$94*$F$95*$F$96*$F$99+_xlpm.PU*$F$91*$F$92*$F$93*$F$94*$F$98+_xlpm.PU*$F$91*$F$92*$F$94*$F$95*$F$98+_xlpm.PU*$F$91*$F$92*$F$94*$F$96*$F$98+_xlpm.PU*$F$91*$F$93*$F$94*$F$95*$F$98+_xlpm.PU*$F$91*$F$94*$F$95*$F$96*$F$98+_xlpm.PU*$F$92*$F$93*$F$94*$F$96*$F$98+_xlpm.PU*$F$92*$F$94*$F$95*$F$96*$F$98+_xlpm.PU*$F$93*$F$94*$F$95*$F$96*$F$98+$F$91*$F$92*$F$93*$F$94*$F$95*$F$98+$F$91*$F$92*$F$94*$F$95*$F$96*$F$98+$F$92*$F$93*$F$94*$F$95*$F$96*$F$98) / ($F$89*_xlpm.PU*$F$91*$F$92*$F$93+$F$89*_xlpm.PU*$F$91*$F$92*$F$95+$F$89*_xlpm.PU*$F$91*$F$92*$F$96+$F$89*_xlpm.PU*$F$91*$F$93*$F$94+$F$89*_xlpm.PU*$F$91*$F$93*$F$95+$F$89*_xlpm.PU*$F$91*$F$94*$F$95+$F$89*_xlpm.PU*$F$91*$F$94*$F$96+$F$89*_xlpm.PU*$F$91*$F$95*$F$96+$F$89*_xlpm.PU*$F$92*$F$93*$F$96+$F$89*_xlpm.PU*$F$92*$F$95*$F$96+$F$89*_xlpm.PU*$F$93*$F$94*$F$96+$F$89*_xlpm.PU*$F$93*$F$95*$F$96+$F$89*_xlpm.PU*$F$94*$F$95*$F$96+$F$89*$F$91*$F$92*$F$93*$F$95+$F$89*$F$91*$F$92*$F$95*$F$96+$F$89*$F$91*$F$93*$F$94*$F$95+$F$89*$F$91*$F$94*$F$95*$F$96+$F$89*$F$92*$F$93*$F$95*$F$96+$F$89*$F$93*$F$94*$F$95*$F$96+_xlpm.PU*$F$91*$F$92*$F$93*$F$94+_xlpm.PU*$F$91*$F$92*$F$94*$F$95+_xlpm.PU*$F$91*$F$92*$F$94*$F$96+_xlpm.PU*$F$91*$F$93*$F$94*$F$95+_xlpm.PU*$F$91*$F$94*$F$95*$F$96+_xlpm.PU*$F$92*$F$93*$F$94*$F$96+_xlpm.PU*$F$92*$F$94*$F$95*$F$96+_xlpm.PU*$F$93*$F$94*$F$95*$F$96+$F$91*$F$92*$F$93*$F$94*$F$95+$F$91*$F$92*$F$94*$F$95*$F$96+$F$92*$F$93*$F$94*$F$95*$F$96), _xlpm.Vspec_rel, (_xlpm.Vspec_abs/_xlpm.VCC-_xlpm.VL_rel)/(1-_xlpm.VL_rel), _xlpm.Tf_max, (LN($D$18-_xlpm.VL_rel)-LN(_xlpm.Vspec_rel))*$K$18*_xlpm.Rbus, IF(_xlpm.Vspec_rel<=0,"Vlow exceeds VIL spec",_xlpm.Tf_max) ) -> Vlow exceeds VIL spec
